Workbook

Sheet Supuestos
A1: SUPUESTOS GENERALES (celdas amarillas = editables)
A3: Escenario (1 = pesimista, 2 = base, 3 = optimista) | B3: 2
A4: Tasa de descuento anual | B4: 0.1
A5: Crecimiento anual de rentas, tarifas y gastos | B5: 0.03
A6: Supervisión e imprevistos de obra | B6: 0.1
A7: Factor de costo de obra - pesimista | B7: 1.15
A8: Factor de costo de obra - base | B8: 1
A9: Factor de costo de obra - optimista | B9: 0.92
A10: Área del terreno (m²) | B10: 820.2
A11: Valor del terreno (S/ por m²) - pesimista | B11: 400
A12: Valor del terreno (S/ por m²) - base (requiere tasación) | B12: 600
A13: Valor del terreno (S/ por m²) - optimista | B13: 850
A14: Valorización anual del terreno - pesimista | B14: 0.03
... A19: Impuesto al alquiler (renta de 1.ª categoría, efectivo) | B19: 0.05
A21: Valor del terreno del escenario elegido (S/) | B21: =Supuestos!$B$10*CHOOSE(Supuestos!$B$3,Supuestos!$B$11,Supuestos!$B$12,Supuestos!$B$13)
A22: Factor de costo del escenario elegido | B22: =CHOOSE(Supuestos!$B$3,Supuestos!$B$7,Supuestos!$B$8,Supuestos!$B$9)
A23: Valorización del terreno del escenario elegido | B23: =CHOOSE(Supuestos!$B$3,Supuestos!$B$14,Supuestos!$B$15,Supuestos!$B$16)
A24: Depósito neto de impuestos | B24: =Supuestos!$B$17*(1-Supuestos!$B$18)
A26: Cómo usar: cambie el escenario o cualquier celda amarilla (aquí o en cada hoja de alternativa); la hoja «Comparación» se recalcula sola.

Sheet Comparación
A1: COMPARACIÓN DE ALTERNATIVAS (escenario elegido en «Supuestos»)
A3: Alt. | B3: Alternativa | C3: Inversión total | D3: VAN al 10 % | E3: TIR | F3: Recupera en el año | G3: Caja neta año 5 | H3: Rinde sobre (terreno + inversión) | I3: TIR contando el terreno | J3: Riesgo | K3: Futuro | L3: Gestión | M3: Capital
A4: L | B4: Ceder la esquina en derecho de superficie (el inquilino construye) | C4: ='L Esquina cedida'!$C$38 | D4: ='L Esquina cedida'!$C$39 | E4: ='L Esquina cedida'!$C$40 | F4: ='L Esquina cedida'!$C$41 | G4: ='L Esquina cedida'!$C$42 | H4: =G4/((1+Supuestos!$B$5)^4)/(C4+Supuestos!$B$21) | I4: ='L Esquina cedida'!$C$43 | J4: medio | K4: alta: al vencer el plazo la edificación queda para el propietario | L4: baja | M4: sin capital
A5: J | B5: Arrendar el lote completo a un operador | C5: ='J Arrendar el lote'!$C$38 | D5: ='J Arrendar el lote'!$C$39 | E5: ='J Arrendar el lote'!$C$40 | F5: ='J Arrendar el lote'!$C$41 | G5: ='J Arrendar el lote'!$C$42 | H5: =G5/((1+Supuestos!$B$5)^4)/(C5+Supuestos!$B$21) | I5: ='J Arrendar el lote'!$C$43 | J5: medio | K5: media: un contrato largo congela el lote (pactar salida anticipada con aviso) | L5: muy baja | M5: sin capital
A6: B | B6: Estacionamiento descubierto de bajo costo | C6: ='B Estac. descubierto'!$C$51 | D6: ='B Estac. descubierto'!$C$52 | E6: ='B Estac. descubierto'!$C$53 | F6: ='B Estac. descubierto'!$C$54 | G6: ='B Estac. descubierto'!$C$55 | H6: =G6/((1+Supuestos!$B$5)^4)/(C6+Supuestos!$B$21) | I6: ='B Estac. descubierto'!$C$56 | J6: medio | K6: alta: casi todo es reversible | L6: media (guardián, cobranza) | M6: propio
A7: C1 | B7: Local de esquina + cochera de abonados | C7: ='C1 Esquina + cochera'!$C$72 | D7: ='C1 Esquina + cochera'!$C$73 | E7: ='C1 Esquina + cochera'!$C$74 | F7: ='C1 Esquina + cochera'!$C$75 | G7: ='C1 Esquina + cochera'!$C$76 | H7: =G7/((1+Supuestos!$B$5)^4)/(C7+Supuestos!$B$21) | I7: ='C1 Esquina + cochera'!$C$77 | J7: medio | K7: alta: la esquina queda lista para crecer y el resto del frente sigue libre | L7: baja | M7: propio
A8: K | B8: Terminal o paradero de vans y colectivos | C8: ='K Terminal de vans'!$C$44 | D8: ='K Terminal de vans'!$C$45 | E8: ='K Terminal de vans'!$C$46 | F8: ='K Terminal de vans'!$C$47 | G8: ='K Terminal de vans'!$C$48 | H8: =G8/((1+Supuestos!$B$5)^4)/(C8+Supuestos!$B$21) | I8: ='K Terminal de vans'!$C$49 | J8: alto | K8: media | L8: alta (autorizaciones, empresas de transporte) | M8: propio
A9: C | B9: Locales en la esquina y el jirón + cochera de abonados | C9: ='C Locales + cochera'!$C$97 | D9: ='C Locales + cochera'!$C$98 | E9: ='C Locales + cochera'!$C$99 | F9: ='C Locales + cochera'!$C$100 | G9: ='C Locales + cochera'!$C$101 | H9: =G9/((1+Supuestos!$B$5)^4)/(C9+Supuestos!$B$21) | I9: ='C Locales + cochera'!$C$102 | J9: medio-alto | K9: alta: deja la estructura lista para crecer en altura | L9: baja (alquiler pasivo) | M9: propio
A10: A | B10: Estacionamiento techado (anteproyecto actual) | C10: ='A Estac. techado'!$C$40 | D10: ='A Estac. techado'!$C$41 | E10: ='A Estac. techado'!$C$42 | F10: ='A Estac. techado'!$C$43 | G10: ='A Estac. techado'!$C$44 | H10: =G10/((1+Supuestos!$B$5)^4)/(C10+Supuestos!$B$21) | I10: ='A Estac. techado'!$C$45 | J10: medio | K10: media: la estructura metálica se puede desmontar, pero ocupa todo el lote | L10: media (guardián, cobranza) | M10: propio
A11: F | B11: Cancha sintética techada (fulbito) | C11: ='F Cancha techada'!$C$51 | D11: ='F Cancha techada'!$C$52 | E11: ='F Cancha techada'!$C$53 | F11: ='F Cancha techada'!$C$54 | G11: ='F Cancha techada'!$C$55 | H11: =G11/((1+Supuestos!$B$5)^4)/(C11+Supuestos!$B$21) | I11: ='F Cancha techada'!$C$56 | J11: alto | K11: baja: ocupa todo el lote y tapa el frente comercial al jirón | L11: alta (horarios nocturnos, encargado) | M11: propio
A12: G | B12: Local de eventos (salón de recepciones) | C12: ='G Local de eventos'!$C$44 | D12: ='G Local de eventos'!$C$45 | E12: ='G Local de eventos'!$C$46 | F12: ='G Local de eventos'!$C$47 | G12: ='G Local de eventos'!$C$48 | H12: =G12/((1+Supuestos!$B$5)^4)/(C12+Supuestos!$B$21) | I12: ='G Local de eventos'!$C$49 | J12: alto | K12: media | L12: alta (agenda, limpieza, vecinos) | M12: propio
A13: E | B13: C + 1 piso de consultorios (año 2) | C13: ='E C + consultorios'!$C$123 | D13: ='E C + consultorios'!$C$124 | E13: ='E C + consultorios'!$C$125 | F13: ='E C + consultorios'!$C$126 | G13: ='E C + consultorios'!$C$127 | H13: =G13/((1+Supuestos!$B$5)^4)/(C13+Supuestos!$B$21) | I13: ='E C + consultorios'!$C$128 | J13: alto | K13: media | L13: media | M13: propio
A14: D | B14: C + 2 pisos de minidepartamentos (año 3) | C14: ='D C + minideptos'!$C$122 | D14: ='D C + minideptos'!$C$123 | E14: ='D C + minideptos'!$C$124 | F14: ='D C + minideptos'!$C$125 | G14: ='D C + minideptos'!$C$126 | H14: =G14/((1+Supuestos!$B$5)^4)/(C14+Supuestos!$B$21) | I14: ='D C + minideptos'!$C$127 | J14: alto | K14: media | L14: media (8 inquilinos) | M14: propio
A15: H | B15: Hostal de 16 habitaciones (3 pisos) | C15: ='H Hostal'!$C$42 | D15: ='H Hostal'!$C$43 | E15: ='H Hostal'!$C$44 | F15: ='H Hostal'!$C$45 | G15: ='H Hostal'!$C$46 | H15: =G15/((1+Supuestos!$B$5)^4)/(C15+Supuestos!$B$21) | I15: ='H Hostal'!$C$47 | J15: alto | K15: media | L15: muy alta (operación 24 h) | M15: propio
B17: Vender el terreno hoy (referencia) | C17: =Supuestos!$B$21 | D17: Precio de venta estimado; depositado al | E17: =Supuestos!$B$17 | F17: rendiría por año: | G17: =Supuestos!$B$21*Supuestos!$B$24 | H17: =Supuestos!$B$24 | I17: =Supuestos!$B$24
B19: Orden: por VAN en el escenario base. «Rinde sobre (terreno + inversión)» compara la caja del año 5 (a precios de hoy) con todo el capital comprometido, incluido el valor del terreno. «TIR contando el terreno» trata el lote como si se aportara hoy a valor de mercado y se recuperara valorizado en el año 20: si es menor que vender y depositar (fila de referencia), la alternativa no paga el terreno.

Sheet L Esquina cedida
A1: L. Ceder la esquina en derecho de superficie (el inquilino construye)
A2: Una cadena, caja, cooperativa o comercio construye su local en la esquina (build-to-suit o derecho de superficie a 10-20 años) y paga renta por el suelo. El fondo queda libre para arrendarlo o para una cochera si se prevenden abonos.
A4: Fase 1: Derecho de superficie en la esquina
D5: Inversión (calculada en su propio modelo, por factor de escenario) | E5: =0.0*Supuestos!$B$22
D6: Año de inversión (opera desde el año siguiente) | E6: 0
D7: Ingreso bruto potencial S/ por mes - pesimista | E7: 560
D8: Ingreso bruto potencial S/ por mes - base | E8: 800
D9: Ingreso bruto potencial S/ por mes - optimista | E9: 1200
D10: Ocupación cobrada - pesimista | E10: 0.95
D11: Ocupación cobrada - base | E11: 0.95
D12: Ocupación cobrada - optimista | E12: 0.95
D13: Gastos fijos S/ por año (personal, energía, mantenimiento, seguro, predial) | E13: 300
D14: Gastos variables (% del ingreso cobrado) | E14: 0
D15: Impuestos (% del ingreso cobrado) | E15: 0.05
D16: Ingreso relativo 1.er año de operación | E16: 0.5
D17: Ingreso relativo 2.º año de operación | E17: 1
D18: Vida útil para valor residual (años) | E18: 1
A20: FLUJO DE CAJA (S/ nominales)
A21: Concepto / año | C21: 0 | D21: 1 | E21: 2 | F21: 3 | G21: 4 | H21: 5 | I21: 6 | J21: 7 | K21: 8 | L21: 9 | M21: 10 | N21: 11 | O21: 12 | P21: 13 | Q21: 14 | R21: 15 | S21: 16 | T21: 17 | U21: 18 | V21: 19 | W21: 20
A22: Inversión - fase 1 | C22: =IF(C$21=$E$6,-$E$5*(1+Supuestos!$B$5)^MAX($E$6-1,0),0) | D22: =IF(D$21=$E$6,-$E$5*(1+Supuestos!$B$5)^MAX($E$6-1,0),0) | E22: =IF(E$21=$E$6,-$E$5*(1+Supuestos!$B$5)^MAX($E$6-1,0),0) | F22: =IF(F$21=$E$6,-$E$5*(1+Supuestos!$B$5)^MAX($E$6-1,0),0) | G22: =IF(G$21=$E$6,-$E$5*(1+Supuestos!$B$5)^MAX($E$6-1,0),0) | H22: =IF(H$21=$E$6,-$E$5*(1+Supuestos!$B$5)^MAX($E$6-1,0),0) | I22: =IF(I$21=$E$6,-$E$5*(1+Supuestos!$B$5)^MAX($E$6-1,0),0) | J22: =IF(J$21=$E$6,-$E$5*(1+Supuestos!$B$5)^MAX($E$6-1,0),0) | ... W22: =IF(W$21=$E$6,-$E$5*(1+Supuestos!$B$5)^MAX($E$6-1,0),0)
A23: Ingresos cobrados - fase 1 | C23: =IF((C$21-$E$6)>=1,CHOOSE(Supuestos!$B$3,$E$7,$E$8,$E$9)*12*CHOOSE(Supuestos!$B$3,$E$10,$E$11,$E$12)*IF((C$21-$E$6)=1,$E$16,IF((C$21-$E$6)=2,$E$17,1))*(1+Supuestos!$B$5)^MAX(C$21-1,0),0) | D23: =IF((D$21-$E$6)>=1,CHOOSE(Supuestos!$B$3,$E$7,$E$8,$E$9)*12*CHOOSE(Supuestos!$B$3,$E$10,$E$11,$E$12)*IF((D$21-$E$6)=1,$E$16,IF((D$21-$E$6)=2,$E$17,1))*(1+Supuestos!$B$5)^MAX(D$21-1,0),0) | E23: =IF((E$21-$E$6)>=1,CHOOSE(Supuestos!$B$3,$E$7,$E$8,$E$9)*12*CHOOSE(Supuestos!$B$3,$E$10,$E$11,$E$12)*IF((E$21-$E$6)=1,$E$16,IF((E$21-$E$6)=2,$E$17,1))*(1+Supuestos!$B$5)^MAX(E$21-1,0),0) | F23: =IF((F$21-$E$6)>=1,CHOOSE(Supuestos!$B$3,$E$7,$E$8,$E$9)*12*CHOOSE(Supuestos!$B$3,$E$10,$E$11,$E$12)*IF((F$21-$E$6)=1,$E$16,IF((F$21-$E$6)=2,$E$17,1))*(1+Supuestos!$B$5)^MAX(F$21-1,0),0) | G23: =IF((G$21-$E$6)>=1,CHOOSE(Supuestos!$B$3,$E$7,$E$8,$E$9)*12*CHOOSE(Supuestos!$B$3,$E$10,$E$11,$E$12)*IF((G$21-$E$6)=1,$E$16,IF((G$21-$E$6)=2,$E$17,1))*(1+Supuestos!$B$5)^MAX(G$21-1,0),0) | H23: =IF((H$21-$E$6)>=1,CHOOSE(Supuestos!$B$3,$E$7,$E$8,$E$9)*12*CHOOSE(Supuestos!$B$3,$E$10,$E$11,$E$12)*IF((H$21-$E$6)=1,$E$16,IF((H$21-$E$6)=2,$E$17,1))*(1+Supuestos!$B$5)^MAX(H$21-1,0),0) | I23: =IF((I$21-$E$6)>=1,CHOOSE(Supuestos!$B$3,$E$7,$E$8,$E$9)*12*CHOOSE(Supuestos!$B$3,$E$10,$E$11,$E$12)*IF((I$21-$E$6)=1,$E$16,IF((I$21-$E$6)=2,$E$17,1))*(1+Supuestos!$B$5)^MAX(I$21-1,0),0) | J23: =IF((J$21-$E$6)>=1,CHOOSE(Supuestos!$B$3,$E$7,$E$8,$E$9)*12*CHOOSE(Supuestos!$B$3,$E$10,$E$11,$E$12)*IF((J$21-$E$6)=1,$E$16,IF((J$21-$E$6)=2,$E$17,1))*(1+Supuestos!$B$5)^MAX(J$21-1,0),0) | ... W23: =IF((W$21-$E$6)>=1,CHOOSE(Supuestos!$B$3,$E$7,$E$8,$E$9)*12*CHOOSE(Supuestos!$B$3,$E$10,$E$11,$E$12)*IF((W$21-$E$6)=1,$E$16,IF((W$21-$E$6)=2,$E$17,1))*(1+Supuestos!$B$5)^MAX(W$21-1,0),0)
A24: Gastos - fase 1 | C24: =IF((C$21-$E$6)>=1,-$E$13*(1+Supuestos!$B$5)^MAX(C$21-1,0)-$E$14*C23,0) | D24: =IF((D$21-$E$6)>=1,-$E$13*(1+Supuestos!$B$5)^MAX(D$21-1,0)-$E$14*D23,0) | E24: =IF((E$21-$E$6)>=1,-$E$13*(1+Supuestos!$B$5)^MAX(E$21-1,0)-$E$14*E23,0) | F24: =IF((F$21-$E$6)>=1,-$E$13*(1+Supuestos!$B$5)^MAX(F$21-1,0)-$E$14*F23,0) | G24: =IF((G$21-$E$6)>=1,-$E$13*(1+Supuestos!$B$5)^MAX(G$21-1,0)-$E$14*G23,0) | H24: =IF((H$21-$E$6)>=1,-$E$13*(1+Supuestos!$B$5)^MAX(H$21-1,0)-$E$14*H23,0) | I24: =IF((I$21-$E$6)>=1,-$E$13*(1+Supuestos!$B$5)^MAX(I$21-1,0)-$E$14*I23,0) | J24: =IF((J$21-$E$6)>=1,-$E$13*(1+Supuestos!$B$5)^MAX(J$21-1,0)-$E$14*J23,0) | ... W24: =IF((W$21-$E$6)>=1,-$E$13*(1+Supuestos!$B$5)^MAX(W$21-1,0)-$E$14*W23,0)
A25: Impuestos - fase 1 | C25: =-$E$15*C23 | D25: =-$E$15*D23 | E25: =-$E$15*E23 | F25: =-$E$15*F23 | G25: =-$E$15*G23 | H25: =-$E$15*H23 | I25: =-$E$15*I23 | J25: =-$E$15*J23 | ... W25: =-$E$15*W23
A26: Reposiciones - fase 1 | C26: =0 | D26: =0 | E26: =0 | F26: =0 | G26: =0 | H26: =0 | I26: =0 | J26: =0 | ... W26: =0
A27: Valor residual (año 20) - fase 1 | C27: =IF(AND(C$21=20,$E$18>1),$E$5*(1+Supuestos!$B$5)^MAX($E$6-1,0)*MAX(0,1-(20-$E$6)/$E$18),0) | D27: =IF(AND(D$21=20,$E$18>1),$E$5*(1+Supuestos!$B$5)^MAX($E$6-1,0)*MAX(0,1-(20-$E$6)/$E$18),0) | E27: =IF(AND(E$21=20,$E$18>1),$E$5*(1+Supuestos!$B$5)^MAX($E$6-1,0)*MAX(0,1-(20-$E$6)/$E$18),0) | F27: =IF(AND(F$21=20,$E$18>1),$E$5*(1+Supuestos!$B$5)^MAX($E$6-1,0)*MAX(0,1-(20-$E$6)/$E$18),0) | G27: =IF(AND(G$21=20,$E$18>1),$E$5*(1+Supuestos!$B$5)^MAX($E$6-1,0)*MAX(0,1-(20-$E$6)/$E$18),0) | H27: =IF(AND(H$21=20,$E$18>1),$E$5*(1+Supuestos!$B$5)^MAX($E$6-1,0)*MAX(0,1-(20-$E$6)/$E$18),0) | I27: =IF(AND(I$21=20,$E$18>1),$E$5*(1+Supuestos!$B$5)^MAX($E$6-1,0)*MAX(0,1-(20-$E$6)/$E$18),0) | J27: =IF(AND(J$21=20,$E$18>1),$E$5*(1+Supuestos!$B$5)^MAX($E$6-1,0)*MAX(0,1-(20-$E$6)/$E$18),0) | ... W27: =IF(AND(W$21=20,$E$18>1),$E$5*(1+Supuestos!$B$5)^MAX($E$6-1,0)*MAX(0,1-(20-$E$6)/$E$18),0)
A28: Inversión | C28: =C22 | D28: =D22 | E28: =E22 | F28: =F22 | G28: =G22 | H28: =H22 | I28: =I22 | J28: =J22 | ... W28: =W22
A29: Ingresos cobrados | C29: =C23 | D29: =D23 | E29: =E23 | F29: =F23 | G29: =G23 | H29: =H23 | I29: =I23 | J29: =J23 | ... W29: =W23
A30: Gastos | C30: =C24 | D30: =D24 | E30: =E24 | F30: =F24 | G30: =G24 | H30: =H24 | I30: =I24 | J30: =J24 | ... W30: =W24
A31: Impuestos | C31: =C25 | D31: =D25 | E31: =E25 | F31: =F25 | G31: =G25 | H31: =H25 | I31: =I25 | J31: =J25 | ... W31: =W25
A32: Reposiciones | C32: =C26 | D32: =D26 | E32: =E26 | F32: =F26 | G32: =G26 | H32: =H26 | I32: =I26 | J32: =J26 | ... W32: =W26
A33: Valor residual (año 20) | C33: =C27 | D33: =D27 | E33: =E27 | F33: =F27 | G33: =G27 | H33: =H27 | I33: =I27 | J33: =J27 | ... W33: =W27
A34: FLUJO NETO | C34: =C28+C29+C30+C31+C32+C33 | D34: =D28+D29+D30+D31+D32+D33 | E34: =E28+E29+E30+E31+E32+E33 | F34: =F28+F29+F30+F31+F32+F33 | G34: =G28+G29+G30+G31+G32+G33 | H34: =H28+H29+H30+H31+H32+H33 | I34: =I28+I29+I30+I31+I32+I33 | J34: =J28+J29+J30+J31+J32+J33 | ... W34: =W28+W29+W30+W31+W32+W33
A35: Caja acumulada (sin valor residual) | C35: =C34-C33 | D35: =C35+D34-D33 | E35: =D35+E34-E33 | F35: =E35+F34-F33 | G35: =F35+G34-G33 | H35: =G35+H34-H33 | I35: =H35+I34-I33 | J35: =I35+J34-J33 | K35: =J35+K34-K33 | ... W35: =V35+W34-W33
A36: Flujo del propietario contando el terreno (lo aporta hoy y lo recupera valorizado) | C36: =C34-Supuestos!$B$21 | D36: =D34 | E36: =E34 | F36: =F34 | G36: =G34 | H36: =H34 | I36: =I34 | J36: =J34 | K36: =K34 | ... V36: =V34 | W36: =W34+Supuestos!$B$21*(1+Supuestos!$B$23)^20
A38: Inversión total | C38: =-SUM(C28:W28)
A39: VAN al 10% | C39: =C34+NPV(Supuestos!$B$4,D34:W34)
A40: TIR | C40: =IFERROR(IRR(C34:W34),IFERROR(IRR(C34:W34,-0.05),"no aplica"))
A41: Año en que se recupera la inversión (acumulado ≥ 0) | C41: =IF(-SUM(C28:W28)=0,"sin inversión",IFERROR(INDEX(C21:W21,MATCH(TRUE,INDEX(C35:W35>=0,0),0)),"no en 20 años"))
A42: Caja neta del año 5 sin inversiones (S/ nominales) | C42: =H34-H28
A43: TIR contando el terreno | C43: =IFERROR(IRR(C36:W36),"no aplica")

Sheet J Arrendar el lote
A1: J. Arrendar el lote completo a un operador
A2: Contrato de 3-10 años con reajuste anual y garantía (depósito de materiales, concesionario o taller de motos, paradero, feria); el inquilino hace sus mejoras.
A4: Fase 1: Arriendo del lote
D5: Inversión (calculada en su propio modelo, por factor de escenario) | E5: =0.0*Supuestos!$B$22
D6: Año de inversión (opera desde el año siguiente) | E6: 0
D7: Ingreso bruto potencial S/ por mes - pesimista | E7: 600
D8: Ingreso bruto potencial S/ por mes - base | E8: 1000
D9: Ingreso bruto potencial S/ por mes - optimista | E9: 1800
D10: Ocupación cobrada - pesimista | E10: 0.6
D11: Ocupación cobrada - base | E11: 0.75
D12: Ocupación cobrada - optimista | E12: 0.9
D13: Gastos fijos S/ por año (personal, energía, mantenimiento, seguro, predial) | E13: 400
D14: Gastos variables (% del ingreso cobrado) | E14: 0
D15: Impuestos (% del ingreso cobrado) | E15: 0.05
D16: Ingreso relativo 1.er año de operación | E16: 0.5
D17: Ingreso relativo 2.º año de operación | E17: 1
D18: Vida útil para valor residual (años) | E18: 1
A20: FLUJO DE CAJA (S/ nominales)
A21: Concepto / año | C21: 0 | D21: 1 | E21: 2 | F21: 3 | G21: 4 | H21: 5 | I21: 6 | J21: 7 | K21: 8 | L21: 9 | M21: 10 | N21: 11 | O21: 12 | P21: 13 | Q21: 14 | R21: 15 | S21: 16 | T21: 17 | U21: 18 | V21: 19 | W21: 20
A22: Inversión - fase 1 | C22: =IF(C$21=$E$6,-$E$5*(1+Supuestos!$B$5)^MAX($E$6-1,0),0) | D22: =IF(D$21=$E$6,-$E$5*(1+Supuestos!$B$5)^MAX($E$6-1,0),0) | E22: =IF(E$21=$E$6,-$E$5*(1+Supuestos!$B$5)^MAX($E$6-1,0),0) | F22: =IF(F$21=$E$6,-$E$5*(1+Supuestos!$B$5)^MAX($E$6-1,0),0) | G22: =IF(G$21=$E$6,-$E$5*(1+Supuestos!$B$5)^MAX($E$6-1,0),0) | H22: =IF(H$21=$E$6,-$E$5*(1+Supuestos!$B$5)^MAX($E$6-1,0),0) | I22: =IF(I$21=$E$6,-$E$5*(1+Supuestos!$B$5)^MAX($E$6-1,0),0) | J22: =IF(J$21=$E$6,-$E$5*(1+Supuestos!$B$5)^MAX($E$6-1,0),0) | ... W22: =IF(W$21=$E$6,-$E$5*(1+Supuestos!$B$5)^MAX($E$6-1,0),0)
A23: Ingresos cobrados - fase 1 | C23: =IF((C$21-$E$6)>=1,CHOOSE(Supuestos!$B$3,$E$7,$E$8,$E$9)*12*CHOOSE(Supuestos!$B$3,$E$10,$E$11,$E$12)*IF((C$21-$E$6)=1,$E$16,IF((C$21-$E$6)=2,$E$17,1))*(1+Supuestos!$B$5)^MAX(C$21-1,0),0) | D23: =IF((D$21-$E$6)>=1,CHOOSE(Supuestos!$B$3,$E$7,$E$8,$E$9)*12*CHOOSE(Supuestos!$B$3,$E$10,$E$11,$E$12)*IF((D$21-$E$6)=1,$E$16,IF((D$21-$E$6)=2,$E$17,1))*(1+Supuestos!$B$5)^MAX(D$21-1,0),0) | E23: =IF((E$21-$E$6)>=1,CHOOSE(Supuestos!$B$3,$E$7,$E$8,$E$9)*12*CHOOSE(Supuestos!$B$3,$E$10,$E$11,$E$12)*IF((E$21-$E$6)=1,$E$16,IF((E$21-$E$6)=2,$E$17,1))*(1+Supuestos!$B$5)^MAX(E$21-1,0),0) | F23: =IF((F$21-$E$6)>=1,CHOOSE(Supuestos!$B$3,$E$7,$E$8,$E$9)*12*CHOOSE(Supuestos!$B$3,$E$10,$E$11,$E$12)*IF((F$21-$E$6)=1,$E$16,IF((F$21-$E$6)=2,$E$17,1))*(1+Supuestos!$B$5)^MAX(F$21-1,0),0) | G23: =IF((G$21-$E$6)>=1,CHOOSE(Supuestos!$B$3,$E$7,$E$8,$E$9)*12*CHOOSE(Supuestos!$B$3,$E$10,$E$11,$E$12)*IF((G$21-$E$6)=1,$E$16,IF((G$21-$E$6)=2,$E$17,1))*(1+Supuestos!$B$5)^MAX(G$21-1,0),0) | H23: =IF((H$21-$E$6)>=1,CHOOSE(Supuestos!$B$3,$E$7,$E$8,$E$9)*12*CHOOSE(Supuestos!$B$3,$E$10,$E$11,$E$12)*IF((H$21-$E$6)=1,$E$16,IF((H$21-$E$6)=2,$E$17,1))*(1+Supuestos!$B$5)^MAX(H$21-1,0),0) | I23: =IF((I$21-$E$6)>=1,CHOOSE(Supuestos!$B$3,$E$7,$E$8,$E$9)*12*CHOOSE(Supuestos!$B$3,$E$10,$E$11,$E$12)*IF((I$21-$E$6)=1,$E$16,IF((I$21-$E$6)=2,$E$17,1))*(1+Supuestos!$B$5)^MAX(I$21-1,0),0) | J23: =IF((J$21-$E$6)>=1,CHOOSE(Supuestos!$B$3,$E$7,$E$8,$E$9)*12*CHOOSE(Supuestos!$B$3,$E$10,$E$11,$E$12)*IF((J$21-$E$6)=1,$E$16,IF((J$21-$E$6)=2,$E$17,1))*(1+Supuestos!$B$5)^MAX(J$21-1,0),0) | ... W23: =IF((W$21-$E$6)>=1,CHOOSE(Supuestos!$B$3,$E$7,$E$8,$E$9)*12*CHOOSE(Supuestos!$B$3,$E$10,$E$11,$E$12)*IF((W$21-$E$6)=1,$E$16,IF((W$21-$E$6)=2,$E$17,1))*(1+Supuestos!$B$5)^MAX(W$21-1,0),0)
A24: Gastos - fase 1 | C24: =IF((C$21-$E$6)>=1,-$E$13*(1+Supuestos!$B$5)^MAX(C$21-1,0)-$E$14*C23,0) | D24: =IF((D$21-$E$6)>=1,-$E$13*(1+Supuestos!$B$5)^MAX(D$21-1,0)-$E$14*D23,0) | E24: =IF((E$21-$E$6)>=1,-$E$13*(1+Supuestos!$B$5)^MAX(E$21-1,0)-$E$14*E23,0) | F24: =IF((F$21-$E$6)>=1,-$E$13*(1+Supuestos!$B$5)^MAX(F$21-1,0)-$E$14*F23,0) | G24: =IF((G$21-$E$6)>=1,-$E$13*(1+Supuestos!$B$5)^MAX(G$21-1,0)-$E$14*G23,0) | H24: =IF((H$21-$E$6)>=1,-$E$13*(1+Supuestos!$B$5)^MAX(H$21-1,0)-$E$14*H23,0) | I24: =IF((I$21-$E$6)>=1,-$E$13*(1+Supuestos!$B$5)^MAX(I$21-1,0)-$E$14*I23,0) | J24: =IF((J$21-$E$6)>=1,-$E$13*(1+Supuestos!$B$5)^MAX(J$21-1,0)-$E$14*J23,0) | ... W24: =IF((W$21-$E$6)>=1,-$E$13*(1+Supuestos!$B$5)^MAX(W$21-1,0)-$E$14*W23,0)
A25: Impuestos - fase 1 | C25: =-$E$15*C23 | D25: =-$E$15*D23 | E25: =-$E$15*E23 | F25: =-$E$15*F23 | G25: =-$E$15*G23 | H25: =-$E$15*H23 | I25: =-$E$15*I23 | J25: =-$E$15*J23 | ... W25: =-$E$15*W23
A26: Reposiciones - fase 1 | C26: =0 | D26: =0 | E26: =0 | F26: =0 | G26: =0 | H26: =0 | I26: =0 | J26: =0 | ... W26: =0
A27: Valor residual (año 20) - fase 1 | C27: =IF(AND(C$21=20,$E$18>1),$E$5*(1+Supuestos!$B$5)^MAX($E$6-1,0)*MAX(0,1-(20-$E$6)/$E$18),0) | D27: =IF(AND(D$21=20,$E$18>1),$E$5*(1+Supuestos!$B$5)^MAX($E$6-1,0)*MAX(0,1-(20-$E$6)/$E$18),0) | E27: =IF(AND(E$21=20,$E$18>1),$E$5*(1+Supuestos!$B$5)^MAX($E$6-1,0)*MAX(0,1-(20-$E$6)/$E$18),0) | F27: =IF(AND(F$21=20,$E$18>1),$E$5*(1+Supuestos!$B$5)^MAX($E$6-1,0)*MAX(0,1-(20-$E$6)/$E$18),0) | G27: =IF(AND(G$21=20,$E$18>1),$E$5*(1+Supuestos!$B$5)^MAX($E$6-1,0)*MAX(0,1-(20-$E$6)/$E$18),0) | H27: =IF(AND(H$21=20,$E$18>1),$E$5*(1+Supuestos!$B$5)^MAX($E$6-1,0)*MAX(0,1-(20-$E$6)/$E$18),0) | I27: =IF(AND(I$21=20,$E$18>1),$E$5*(1+Supuestos!$B$5)^MAX($E$6-1,0)*MAX(0,1-(20-$E$6)/$E$18),0) | J27: =IF(AND(J$21=20,$E$18>1),$E$5*(1+Supuestos!$B$5)^MAX($E$6-1,0)*MAX(0,1-(20-$E$6)/$E$18),0) | ... W27: =IF(AND(W$21=20,$E$18>1),$E$5*(1+Supuestos!$B$5)^MAX($E$6-1,0)*MAX(0,1-(20-$E$6)/$E$18),0)
A28: Inversión | C28: =C22 | D28: =D22 | E28: =E22 | F28: =F22 | G28: =G22 | H28: =H22 | I28: =I22 | J28: =J22 | ... W28: =W22
A29: Ingresos cobrados | C29: =C23 | D29: =D23 | E29: =E23 | F29: =F23 | G29: =G23 | H29: =H23 | I29: =I23 | J29: =J23 | ... W29: =W23
A30: Gastos | C30: =C24 | D30: =D24 | E30: =E24 | F30: =F24 | G30: =G24 | H30: =H24 | I30: =I24 | J30: =J24 | ... W30: =W24
A31: Impuestos | C31: =C25 | D31: =D25 | E31: =E25 | F31: =F25 | G31: =G25 | H31: =H25 | I31: =I25 | J31: =J25 | ... W31: =W25
A32: Reposiciones | C32: =C26 | D32: =D26 | E32: =E26 | F32: =F26 | G32: =G26 | H32: =H26 | I32: =I26 | J32: =J26 | ... W32: =W26
A33: Valor residual (año 20) | C33: =C27 | D33: =D27 | E33: =E27 | F33: =F27 | G33: =G27 | H33: =H27 | I33: =I27 | J33: =J27 | ... W33: =W27
A34: FLUJO NETO | C34: =C28+C29+C30+C31+C32+C33 | D34: =D28+D29+D30+D31+D32+D33 | E34: =E28+E29+E30+E31+E32+E33 | F34: =F28+F29+F30+F31+F32+F33 | G34: =G28+G29+G30+G31+G32+G33 | H34: =H28+H29+H30+H31+H32+H33 | I34: =I28+I29+I30+I31+I32+I33 | J34: =J28+J29+J30+J31+J32+J33 | ... W34: =W28+W29+W30+W31+W32+W33
A35: Caja acumulada (sin valor residual) | C35: =C34-C33 | D35: =C35+D34-D33 | E35: =D35+E34-E33 | F35: =E35+F34-F33 | G35: =F35+G34-G33 | H35: =G35+H34-H33 | I35: =H35+I34-I33 | J35: =I35+J34-J33 | K35: =J35+K34-K33 | ... W35: =V35+W34-W33
A36: Flujo del propietario contando el terreno (lo aporta hoy y lo recupera valorizado) | C36: =C34-Supuestos!$B$21 | D36: =D34 | E36: =E34 | F36: =F34 | G36: =G34 | H36: =H34 | I36: =I34 | J36: =J34 | K36: =K34 | ... V36: =V34 | W36: =W34+Supuestos!$B$21*(1+Supuestos!$B$23)^20
A38: Inversión total | C38: =-SUM(C28:W28)
A39: VAN al 10% | C39: =C34+NPV(Supuestos!$B$4,D34:W34)
A40: TIR | C40: =IFERROR(IRR(C34:W34),IFERROR(IRR(C34:W34,-0.05),"no aplica"))
A41: Año en que se recupera la inversión (acumulado ≥ 0) | C41: =IF(-SUM(C28:W28)=0,"sin inversión",IFERROR(INDEX(C21:W21,MATCH(TRUE,INDEX(C35:W35>=0,0),0)),"no en 20 años"))
A42: Caja neta del año 5 sin inversiones (S/ nominales) | C42: =H34-H28
A43: TIR contando el terreno | C43: =IFERROR(IRR(C36:W36),"no aplica")

Sheet B Estac. descubierto
A1: B. Estacionamiento descubierto de bajo costo
A2: Afirmado, cerco de malla, caseta y portones; 28 plazas a la intemperie, con guardián. Demanda base: 10 abonados a S/ 85, 7 autos de rotación al día a S/ 3.50 y 4 motos a S/ 35.
A4: Fase 1: Estacionamiento descubierto
A5: Partida | B5: Und. | C5: Cantidad | D5: P. unitario | E5: Parcial
A6: Afirmado compactado e=0.20 m con bombeo | B6: m² | C6: 680 | D6: 40 | E6: =C6*D6
A7: Cerco de malla galvanizada h=2.0 m en frentes | B7: ml | C7: 44 | D7: 120 | E7: =C7*D7
A8: Portones de malla 3.0 m (ingreso y salida) | B8: und | C8: 2 | D8: 2200 | E8: =C8*D8
A9: Caseta prefabricada de control con SS.HH. básico | B9: und | C9: 1 | D9: 9000 | E9: =C9*D9
A10: Postes con reflector LED | B10: und | C10: 3 | D10: 1800 | E10: =C10*D10
A11: Cuneta de drenaje y descarga a la vía | B11: ml | C11: 25 | D11: 180 | E11: =C11*D11
A12: Señalización, topellantas y numeración | B12: glb | C12: 1 | D12: 4000 | E12: =C12*D12
A13: Licencia de funcionamiento, ITSE y trámites | B13: glb | C13: 1 | D13: 3500 | E13: =C13*D13
D14: Inversión (con imprevistos y factor de escenario) | E14: =SUM(E6:E13)*(1+Supuestos!$B$6)*Supuestos!$B$22
D15: Año de inversión (opera desde el año siguiente) | E15: 0
D16: Ingreso bruto potencial S/ por mes - pesimista | E16: 1140
D17: Ingreso bruto potencial S/ por mes - base | E17: 1725
D18: Ingreso bruto potencial S/ por mes - optimista | E18: 2555
D19: Ocupación cobrada - pesimista | E19: 1
D20: Ocupación cobrada - base | E20: 1
D21: Ocupación cobrada - optimista | E21: 1
D22: Gastos fijos S/ por año (personal, energía, mantenimiento, seguro, predial) | E22: 22545.4
D23: Gastos variables (% del ingreso cobrado) | E23: 0
D24: Impuestos (% del ingreso cobrado) | E24: 0
D25: Ingreso relativo 1.er año de operación | E25: 0.6
D26: Ingreso relativo 2.º año de operación | E26: 0.85
... D31: Reposición 2: monto a precios de hoy | E31: 28600
A33: FLUJO DE CAJA (S/ nominales)
A34: Concepto / año | C34: 0 | D34: 1 | E34: 2 | F34: 3 | G34: 4 | H34: 5 | I34: 6 | J34: 7 | K34: 8 | L34: 9 | M34: 10 | N34: 11 | O34: 12 | P34: 13 | Q34: 14 | R34: 15 | S34: 16 | T34: 17 | U34: 18 | V34: 19 | W34: 20
A35: Inversión - fase 1 | C35: =IF(C$34=$E$15,-$E$14*(1+Supuestos!$B$5)^MAX($E$15-1,0),0) | D35: =IF(D$34=$E$15,-$E$14*(1+Supuestos!$B$5)^MAX($E$15-1,0),0) | E35: =IF(E$34=$E$15,-$E$14*(1+Supuestos!$B$5)^MAX($E$15-1,0),0) | F35: =IF(F$34=$E$15,-$E$14*(1+Supuestos!$B$5)^MAX($E$15-1,0),0) | G35: =IF(G$34=$E$15,-$E$14*(1+Supuestos!$B$5)^MAX($E$15-1,0),0) | H35: =IF(H$34=$E$15,-$E$14*(1+Supuestos!$B$5)^MAX($E$15-1,0),0) | I35: =IF(I$34=$E$15,-$E$14*(1+Supuestos!$B$5)^MAX($E$15-1,0),0) | J35: =IF(J$34=$E$15,-$E$14*(1+Supuestos!$B$5)^MAX($E$15-1,0),0) | ... W35: =IF(W$34=$E$15,-$E$14*(1+Supuestos!$B$5)^MAX($E$15-1,0),0)
A36: Ingresos cobrados - fase 1 | C36: =IF((C$34-$E$15)>=1,CHOOSE(Supuestos!$B$3,$E$16,$E$17,$E$18)*12*CHOOSE(Supuestos!$B$3,$E$19,$E$20,$E$21)*IF((C$34-$E$15)=1,$E$25,IF((C$34-$E$15)=2,$E$26,1))*(1+Supuestos!$B$5)^MAX(C$34-1,0),0) | D36: =IF((D$34-$E$15)>=1,CHOOSE(Supuestos!$B$3,$E$16,$E$17,$E$18)*12*CHOOSE(Supuestos!$B$3,$E$19,$E$20,$E$21)*IF((D$34-$E$15)=1,$E$25,IF((D$34-$E$15)=2,$E$26,1))*(1+Supuestos!$B$5)^MAX(D$34-1,0),0) | E36: =IF((E$34-$E$15)>=1,CHOOSE(Supuestos!$B$3,$E$16,$E$17,$E$18)*12*CHOOSE(Supuestos!$B$3,$E$19,$E$20,$E$21)*IF((E$34-$E$15)=1,$E$25,IF((E$34-$E$15)=2,$E$26,1))*(1+Supuestos!$B$5)^MAX(E$34-1,0),0) | F36: =IF((F$34-$E$15)>=1,CHOOSE(Supuestos!$B$3,$E$16,$E$17,$E$18)*12*CHOOSE(Supuestos!$B$3,$E$19,$E$20,$E$21)*IF((F$34-$E$15)=1,$E$25,IF((F$34-$E$15)=2,$E$26,1))*(1+Supuestos!$B$5)^MAX(F$34-1,0),0) | G36: =IF((G$34-$E$15)>=1,CHOOSE(Supuestos!$B$3,$E$16,$E$17,$E$18)*12*CHOOSE(Supuestos!$B$3,$E$19,$E$20,$E$21)*IF((G$34-$E$15)=1,$E$25,IF((G$34-$E$15)=2,$E$26,1))*(1+Supuestos!$B$5)^MAX(G$34-1,0),0) | H36: =IF((H$34-$E$15)>=1,CHOOSE(Supuestos!$B$3,$E$16,$E$17,$E$18)*12*CHOOSE(Supuestos!$B$3,$E$19,$E$20,$E$21)*IF((H$34-$E$15)=1,$E$25,IF((H$34-$E$15)=2,$E$26,1))*(1+Supuestos!$B$5)^MAX(H$34-1,0),0) | I36: =IF((I$34-$E$15)>=1,CHOOSE(Supuestos!$B$3,$E$16,$E$17,$E$18)*12*CHOOSE(Supuestos!$B$3,$E$19,$E$20,$E$21)*IF((I$34-$E$15)=1,$E$25,IF((I$34-$E$15)=2,$E$26,1))*(1+Supuestos!$B$5)^MAX(I$34-1,0),0) | J36: =IF((J$34-$E$15)>=1,CHOOSE(Supuestos!$B$3,$E$16,$E$17,$E$18)*12*CHOOSE(Supuestos!$B$3,$E$19,$E$20,$E$21)*IF((J$34-$E$15)=1,$E$25,IF((J$34-$E$15)=2,$E$26,1))*(1+Supuestos!$B$5)^MAX(J$34-1,0),0) | ... W36: =IF((W$34-$E$15)>=1,CHOOSE(Supuestos!$B$3,$E$16,$E$17,$E$18)*12*CHOOSE(Supuestos!$B$3,$E$19,$E$20,$E$21)*IF((W$34-$E$15)=1,$E$25,IF((W$34-$E$15)=2,$E$26,1))*(1+Supuestos!$B$5)^MAX(W$34-1,0),0)
A37: Gastos - fase 1 | C37: =IF((C$34-$E$15)>=1,-$E$22*(1+Supuestos!$B$5)^MAX(C$34-1,0)-$E$23*C36,0) | D37: =IF((D$34-$E$15)>=1,-$E$22*(1+Supuestos!$B$5)^MAX(D$34-1,0)-$E$23*D36,0) | E37: =IF((E$34-$E$15)>=1,-$E$22*(1+Supuestos!$B$5)^MAX(E$34-1,0)-$E$23*E36,0) | F37: =IF((F$34-$E$15)>=1,-$E$22*(1+Supuestos!$B$5)^MAX(F$34-1,0)-$E$23*F36,0) | G37: =IF((G$34-$E$15)>=1,-$E$22*(1+Supuestos!$B$5)^MAX(G$34-1,0)-$E$23*G36,0) | H37: =IF((H$34-$E$15)>=1,-$E$22*(1+Supuestos!$B$5)^MAX(H$34-1,0)-$E$23*H36,0) | I37: =IF((I$34-$E$15)>=1,-$E$22*(1+Supuestos!$B$5)^MAX(I$34-1,0)-$E$23*I36,0) | J37: =IF((J$34-$E$15)>=1,-$E$22*(1+Supuestos!$B$5)^MAX(J$34-1,0)-$E$23*J36,0) | ... W37: =IF((W$34-$E$15)>=1,-$E$22*(1+Supuestos!$B$5)^MAX(W$34-1,0)-$E$23*W36,0)
A38: Impuestos - fase 1 | C38: =-$E$24*C36 | D38: =-$E$24*D36 | E38: =-$E$24*E36 | F38: =-$E$24*F36 | G38: =-$E$24*G36 | H38: =-$E$24*H36 | I38: =-$E$24*I36 | J38: =-$E$24*J36 | ... W38: =-$E$24*W36
A39: Reposiciones - fase 1 | C39: =IF((C$34-$E$15)=$E$28,-$E$29*(1+Supuestos!$B$5)^MAX(C$34-1,0)*Supuestos!$B$22,0)+IF((C$34-$E$15)=$E$30,-$E$31*(1+Supuestos!$B$5)^MAX(C$34-1,0)*Supuestos!$B$22,0) | D39: =IF((D$34-$E$15)=$E$28,-$E$29*(1+Supuestos!$B$5)^MAX(D$34-1,0)*Supuestos!$B$22,0)+IF((D$34-$E$15)=$E$30,-$E$31*(1+Supuestos!$B$5)^MAX(D$34-1,0)*Supuestos!$B$22,0) | E39: =IF((E$34-$E$15)=$E$28,-$E$29*(1+Supuestos!$B$5)^MAX(E$34-1,0)*Supuestos!$B$22,0)+IF((E$34-$E$15)=$E$30,-$E$31*(1+Supuestos!$B$5)^MAX(E$34-1,0)*Supuestos!$B$22,0) | F39: =IF((F$34-$E$15)=$E$28,-$E$29*(1+Supuestos!$B$5)^MAX(F$34-1,0)*Supuestos!$B$22,0)+IF((F$34-$E$15)=$E$30,-$E$31*(1+Supuestos!$B$5)^MAX(F$34-1,0)*Supuestos!$B$22,0) | G39: =IF((G$34-$E$15)=$E$28,-$E$29*(1+Supuestos!$B$5)^MAX(G$34-1,0)*Supuestos!$B$22,0)+IF((G$34-$E$15)=$E$30,-$E$31*(1+Supuestos!$B$5)^MAX(G$34-1,0)*Supuestos!$B$22,0) | H39: =IF((H$34-$E$15)=$E$28,-$E$29*(1+Supuestos!$B$5)^MAX(H$34-1,0)*Supuestos!$B$22,0)+IF((H$34-$E$15)=$E$30,-$E$31*(1+Supuestos!$B$5)^MAX(H$34-1,0)*Supuestos!$B$22,0) | I39: =IF((I$34-$E$15)=$E$28,-$E$29*(1+Supuestos!$B$5)^MAX(I$34-1,0)*Supuestos!$B$22,0)+IF((I$34-$E$15)=$E$30,-$E$31*(1+Supuestos!$B$5)^MAX(I$34-1,0)*Supuestos!$B$22,0) | J39: =IF((J$34-$E$15)=$E$28,-$E$29*(1+Supuestos!$B$5)^MAX(J$34-1,0)*Supuestos!$B$22,0)+IF((J$34-$E$15)=$E$30,-$E$31*(1+Supuestos!$B$5)^MAX(J$34-1,0)*Supuestos!$B$22,0) | ... W39: =IF((W$34-$E$15)=$E$28,-$E$29*(1+Supuestos!$B$5)^MAX(W$34-1,0)*Supuestos!$B$22,0)+IF((W$34-$E$15)=$E$30,-$E$31*(1+Supuestos!$B$5)^MAX(W$34-1,0)*Supuestos!$B$22,0)
A40: Valor residual (año 20) - fase 1 | C40: =IF(AND(C$34=20,$E$27>1),$E$14*(1+Supuestos!$B$5)^MAX($E$15-1,0)*MAX(0,1-(20-$E$15)/$E$27),0) | D40: =IF(AND(D$34=20,$E$27>1),$E$14*(1+Supuestos!$B$5)^MAX($E$15-1,0)*MAX(0,1-(20-$E$15)/$E$27),0) | E40: =IF(AND(E$34=20,$E$27>1),$E$14*(1+Supuestos!$B$5)^MAX($E$15-1,0)*MAX(0,1-(20-$E$15)/$E$27),0) | F40: =IF(AND(F$34=20,$E$27>1),$E$14*(1+Supuestos!$B$5)^MAX($E$15-1,0)*MAX(0,1-(20-$E$15)/$E$27),0) | G40: =IF(AND(G$34=20,$E$27>1),$E$14*(1+Supuestos!$B$5)^MAX($E$15-1,0)*MAX(0,1-(20-$E$15)/$E$27),0) | H40: =IF(AND(H$34=20,$E$27>1),$E$14*(1+Supuestos!$B$5)^MAX($E$15-1,0)*MAX(0,1-(20-$E$15)/$E$27),0) | I40: =IF(AND(I$34=20,$E$27>1),$E$14*(1+Supuestos!$B$5)^MAX($E$15-1,0)*MAX(0,1-(20-$E$15)/$E$27),0) | J40: =IF(AND(J$34=20,$E$27>1),$E$14*(1+Supuestos!$B$5)^MAX($E$15-1,0)*MAX(0,1-(20-$E$15)/$E$27),0) | ... W40: =IF(AND(W$34=20,$E$27>1),$E$14*(1+Supuestos!$B$5)^MAX($E$15-1,0)*MAX(0,1-(20-$E$15)/$E$27),0)
A41: Inversión | C41: =C35 | D41: =D35 | E41: =E35 | F41: =F35 | G41: =G35 | H41: =H35 | I41: =I35 | J41: =J35 | ... W41: =W35
A42: Ingresos cobrados | C42: =C36 | D42: =D36 | E42: =E36 | F42: =F36 | G42: =G36 | H42: =H36 | I42: =I36 | J42: =J36 | ... W42: =W36
A43: Gastos | C43: =C37 | D43: =D37 | E43: =E37 | F43: =F37 | G43: =G37 | H43: =H37 | I43: =I37 | J43: =J37 | ... W43: =W37
A44: Impuestos | C44: =C38 | D44: =D38 | E44: =E38 | F44: =F38 | G44: =G38 | H44: =H38 | I44: =I38 | J44: =J38 | ... W44: =W38
A45: Reposiciones | C45: =C39 | D45: =D39 | E45: =E39 | F45: =F39 | G45: =G39 | H45: =H39 | I45: =I39 | J45: =J39 | ... W45: =W39
A46: Valor residual (año 20) | C46: =C40 | D46: =D40 | E46: =E40 | F46: =F40 | G46: =G40 | H46: =H40 | I46: =I40 | J46: =J40 | ... W46: =W40
...

Sheet C1 Esquina + cochera
A1: C1. Local de esquina + cochera de abonados
A2: Solo el local ancla de 100 m² en la esquina (estructura para 3 pisos) y la cochera del fondo; los 3 locales del jirón quedan para una etapa posterior.
A4: Fase 1: Local de esquina (100 m²)
A5: Partida | B5: Und. | C5: Cantidad | D5: P. unitario | E5: Parcial
A6: Local de esquina de 100 m² en pórticos de C.A. diseñados para 3 pisos, puertas enrollables y SS.HH. | B6: m² | C6: 100 | D6: 1500 | E6: =C6*D6
A7: Estudio de suelos, proyecto y licencia | B7: glb | C7: 1 | D7: 20000 | E7: =C7*D7
D8: Inversión (con imprevistos y factor de escenario) | E8: =SUM(E6:E7)*(1+Supuestos!$B$6)*Supuestos!$B$22
D9: Año de inversión (opera desde el año siguiente) | E9: 0
D10: Ingreso bruto potencial S/ por mes - pesimista | E10: 1000
D11: Ingreso bruto potencial S/ por mes - base | E11: 1300
D12: Ingreso bruto potencial S/ por mes - optimista | E12: 2000
D13: Ocupación cobrada - pesimista | E13: 0.7
D14: Ocupación cobrada - base | E14: 0.8
D15: Ocupación cobrada - optimista | E15: 0.9
D16: Gastos fijos S/ por año (personal, energía, mantenimiento, seguro, predial) | E16: 2500
D17: Gastos variables (% del ingreso cobrado) | E17: 0
D18: Impuestos (% del ingreso cobrado) | E18: 0.05
D19: Ingreso relativo 1.er año de operación | E19: 0.5
D20: Ingreso relativo 2.º año de operación | E20: 0.8
D21: Vida útil para valor residual (años) | E21: 50
A23: Fase 2: Cochera de abonados (fondo, descubierta)
A24: Partida | B24: Und. | C24: Cantidad | D24: P. unitario | E24: Parcial
A25: Afirmado compactado e=0.20 m con bombeo | B25: m² | C25: 540 | D25: 40 | E25: =C25*D25
A26: Drenaje del patio | B26: ml | C26: 20 | D26: 220 | E26: =C26*D26
A27: Portón telescópico automatizado de 6.5 m con 40 controles + puerta peatonal | B27: glb | C27: 1 | D27: 15500 | E27: =C27*D27
A28: Cerco de albañilería en el fondo C-D | B28: ml | C28: 30 | D28: 330 | E28: =C28*D28
A29: Iluminación LED y CCTV de 4 cámaras | B29: glb | C29: 1 | D29: 7500 | E29: =C29*D29
A30: Señalización, numeración y topellantas | B30: glb | C30: 1 | D30: 2400 | E30: =C30*D30
D31: Inversión (con imprevistos y factor de escenario) | E31: =SUM(E25:E30)*(1+Supuestos!$B$6)*Supuestos!$B$22
D32: Año de inversión (opera desde el año siguiente) | E32: 0
D33: Ingreso bruto potencial S/ por mes - pesimista | E33: 480
D34: Ingreso bruto potencial S/ por mes - base | E34: 900
D35: Ingreso bruto potencial S/ por mes - optimista | E35: 1440
D36: Ocupación cobrada - pesimista | E36: 0.6
D37: Ocupación cobrada - base | E37: 0.7
D38: Ocupación cobrada - optimista | E38: 0.8
D39: Gastos fijos S/ por año (personal, energía, mantenimiento, seguro, predial) | E39: 3200
D40: Gastos variables (% del ingreso cobrado) | E40: 0
D41: Impuestos (% del ingreso cobrado) | E41: 0
D42: Ingreso relativo 1.er año de operación | E42: 0.6
...

Sheet K Terminal de vans
A1: K. Terminal o paradero de vans y colectivos
A2: Patio de maniobras de concreto, andenes techados, 4 boleterías, sala de espera y SS.HH.
A4: Fase 1: Terminal de vans
A5: Partida | B5: Und. | C5: Cantidad | D5: P. unitario | E5: Parcial
A6: Pavimento de concreto para patio de maniobras | B6: m² | C6: 480 | D6: 130 | E6: =C6*D6
A7: Techado metálico de andenes | B7: m² | C7: 150 | D7: 400 | E7: =C7*D7
A8: Sala de espera, 4 boleterías y SS.HH. | B8: m² | C8: 120 | D8: 1300 | E8: =C8*D8
A9: Cerco, portones y señalización | B9: glb | C9: 1 | D9: 20000 | E9: =C9*D9
A10: Estudio de impacto vial, habilitación técnica MTC y licencias (Modalidad D) | B10: glb | C10: 1 | D10: 25000 | E10: =C10*D10
D11: Inversión (con imprevistos y factor de escenario) | E11: =SUM(E6:E10)*(1+Supuestos!$B$6)*Supuestos!$B$22
D12: Año de inversión (opera desde el año siguiente) | E12: 0
D13: Ingreso bruto potencial S/ por mes - pesimista | E13: 2680
D14: Ingreso bruto potencial S/ por mes - base | E14: 4800
D15: Ingreso bruto potencial S/ por mes - optimista | E15: 7400
D16: Ocupación cobrada - pesimista | E16: 1
D17: Ocupación cobrada - base | E17: 1
D18: Ocupación cobrada - optimista | E18: 1
D19: Gastos fijos S/ por año (personal, energía, mantenimiento, seguro, predial) | E19: 33945.4
D20: Gastos variables (% del ingreso cobrado) | E20: 0
D21: Impuestos (% del ingreso cobrado) | E21: 0.03
D22: Ingreso relativo 1.er año de operación | E22: 0.6
D23: Ingreso relativo 2.º año de operación | E23: 0.85
D24: Vida útil para valor residual (años) | E24: 40
A26: FLUJO DE CAJA (S/ nominales)
A27: Concepto / año | C27: 0 | D27: 1 | E27: 2 | F27: 3 | G27: 4 | H27: 5 | I27: 6 | J27: 7 | K27: 8 | L27: 9 | M27: 10 | N27: 11 | O27: 12 | P27: 13 | Q27: 14 | R27: 15 | S27: 16 | T27: 17 | U27: 18 | V27: 19 | W27: 20
A28: Inversión - fase 1 | C28: =IF(C$27=$E$12,-$E$11*(1+Supuestos!$B$5)^MAX($E$12-1,0),0) | D28: =IF(D$27=$E$12,-$E$11*(1+Supuestos!$B$5)^MAX($E$12-1,0),0) | E28: =IF(E$27=$E$12,-$E$11*(1+Supuestos!$B$5)^MAX($E$12-1,0),0) | F28: =IF(F$27=$E$12,-$E$11*(1+Supuestos!$B$5)^MAX($E$12-1,0),0) | G28: =IF(G$27=$E$12,-$E$11*(1+Supuestos!$B$5)^MAX($E$12-1,0),0) | H28: =IF(H$27=$E$12,-$E$11*(1+Supuestos!$B$5)^MAX($E$12-1,0),0) | I28: =IF(I$27=$E$12,-$E$11*(1+Supuestos!$B$5)^MAX($E$12-1,0),0) | J28: =IF(J$27=$E$12,-$E$11*(1+Supuestos!$B$5)^MAX($E$12-1,0),0) | ... W28: =IF(W$27=$E$12,-$E$11*(1+Supuestos!$B$5)^MAX($E$12-1,0),0)
A29: Ingresos cobrados - fase 1 | C29: =IF((C$27-$E$12)>=1,CHOOSE(Supuestos!$B$3,$E$13,$E$14,$E$15)*12*CHOOSE(Supuestos!$B$3,$E$16,$E$17,$E$18)*IF((C$27-$E$12)=1,$E$22,IF((C$27-$E$12)=2,$E$23,1))*(1+Supuestos!$B$5)^MAX(C$27-1,0),0) | D29: =IF((D$27-$E$12)>=1,CHOOSE(Supuestos!$B$3,$E$13,$E$14,$E$15)*12*CHOOSE(Supuestos!$B$3,$E$16,$E$17,$E$18)*IF((D$27-$E$12)=1,$E$22,IF((D$27-$E$12)=2,$E$23,1))*(1+Supuestos!$B$5)^MAX(D$27-1,0),0) | E29: =IF((E$27-$E$12)>=1,CHOOSE(Supuestos!$B$3,$E$13,$E$14,$E$15)*12*CHOOSE(Supuestos!$B$3,$E$16,$E$17,$E$18)*IF((E$27-$E$12)=1,$E$22,IF((E$27-$E$12)=2,$E$23,1))*(1+Supuestos!$B$5)^MAX(E$27-1,0),0) | F29: =IF((F$27-$E$12)>=1,CHOOSE(Supuestos!$B$3,$E$13,$E$14,$E$15)*12*CHOOSE(Supuestos!$B$3,$E$16,$E$17,$E$18)*IF((F$27-$E$12)=1,$E$22,IF((F$27-$E$12)=2,$E$23,1))*(1+Supuestos!$B$5)^MAX(F$27-1,0),0) | G29: =IF((G$27-$E$12)>=1,CHOOSE(Supuestos!$B$3,$E$13,$E$14,$E$15)*12*CHOOSE(Supuestos!$B$3,$E$16,$E$17,$E$18)*IF((G$27-$E$12)=1,$E$22,IF((G$27-$E$12)=2,$E$23,1))*(1+Supuestos!$B$5)^MAX(G$27-1,0),0) | H29: =IF((H$27-$E$12)>=1,CHOOSE(Supuestos!$B$3,$E$13,$E$14,$E$15)*12*CHOOSE(Supuestos!$B$3,$E$16,$E$17,$E$18)*IF((H$27-$E$12)=1,$E$22,IF((H$27-$E$12)=2,$E$23,1))*(1+Supuestos!$B$5)^MAX(H$27-1,0),0) | I29: =IF((I$27-$E$12)>=1,CHOOSE(Supuestos!$B$3,$E$13,$E$14,$E$15)*12*CHOOSE(Supuestos!$B$3,$E$16,$E$17,$E$18)*IF((I$27-$E$12)=1,$E$22,IF((I$27-$E$12)=2,$E$23,1))*(1+Supuestos!$B$5)^MAX(I$27-1,0),0) | J29: =IF((J$27-$E$12)>=1,CHOOSE(Supuestos!$B$3,$E$13,$E$14,$E$15)*12*CHOOSE(Supuestos!$B$3,$E$16,$E$17,$E$18)*IF((J$27-$E$12)=1,$E$22,IF((J$27-$E$12)=2,$E$23,1))*(1+Supuestos!$B$5)^MAX(J$27-1,0),0) | ... W29: =IF((W$27-$E$12)>=1,CHOOSE(Supuestos!$B$3,$E$13,$E$14,$E$15)*12*CHOOSE(Supuestos!$B$3,$E$16,$E$17,$E$18)*IF((W$27-$E$12)=1,$E$22,IF((W$27-$E$12)=2,$E$23,1))*(1+Supuestos!$B$5)^MAX(W$27-1,0),0)
A30: Gastos - fase 1 | C30: =IF((C$27-$E$12)>=1,-$E$19*(1+Supuestos!$B$5)^MAX(C$27-1,0)-$E$20*C29,0) | D30: =IF((D$27-$E$12)>=1,-$E$19*(1+Supuestos!$B$5)^MAX(D$27-1,0)-$E$20*D29,0) | E30: =IF((E$27-$E$12)>=1,-$E$19*(1+Supuestos!$B$5)^MAX(E$27-1,0)-$E$20*E29,0) | F30: =IF((F$27-$E$12)>=1,-$E$19*(1+Supuestos!$B$5)^MAX(F$27-1,0)-$E$20*F29,0) | G30: =IF((G$27-$E$12)>=1,-$E$19*(1+Supuestos!$B$5)^MAX(G$27-1,0)-$E$20*G29,0) | H30: =IF((H$27-$E$12)>=1,-$E$19*(1+Supuestos!$B$5)^MAX(H$27-1,0)-$E$20*H29,0) | I30: =IF((I$27-$E$12)>=1,-$E$19*(1+Supuestos!$B$5)^MAX(I$27-1,0)-$E$20*I29,0) | J30: =IF((J$27-$E$12)>=1,-$E$19*(1+Supuestos!$B$5)^MAX(J$27-1,0)-$E$20*J29,0) | ... W30: =IF((W$27-$E$12)>=1,-$E$19*(1+Supuestos!$B$5)^MAX(W$27-1,0)-$E$20*W29,0)
A31: Impuestos - fase 1 | C31: =-$E$21*C29 | D31: =-$E$21*D29 | E31: =-$E$21*E29 | F31: =-$E$21*F29 | G31: =-$E$21*G29 | H31: =-$E$21*H29 | I31: =-$E$21*I29 | J31: =-$E$21*J29 | ... W31: =-$E$21*W29
A32: Reposiciones - fase 1 | C32: =0 | D32: =0 | E32: =0 | F32: =0 | G32: =0 | H32: =0 | I32: =0 | J32: =0 | ... W32: =0
A33: Valor residual (año 20) - fase 1 | C33: =IF(AND(C$27=20,$E$24>1),$E$11*(1+Supuestos!$B$5)^MAX($E$12-1,0)*MAX(0,1-(20-$E$12)/$E$24),0) | D33: =IF(AND(D$27=20,$E$24>1),$E$11*(1+Supuestos!$B$5)^MAX($E$12-1,0)*MAX(0,1-(20-$E$12)/$E$24),0) | E33: =IF(AND(E$27=20,$E$24>1),$E$11*(1+Supuestos!$B$5)^MAX($E$12-1,0)*MAX(0,1-(20-$E$12)/$E$24),0) | F33: =IF(AND(F$27=20,$E$24>1),$E$11*(1+Supuestos!$B$5)^MAX($E$12-1,0)*MAX(0,1-(20-$E$12)/$E$24),0) | G33: =IF(AND(G$27=20,$E$24>1),$E$11*(1+Supuestos!$B$5)^MAX($E$12-1,0)*MAX(0,1-(20-$E$12)/$E$24),0) | H33: =IF(AND(H$27=20,$E$24>1),$E$11*(1+Supuestos!$B$5)^MAX($E$12-1,0)*MAX(0,1-(20-$E$12)/$E$24),0) | I33: =IF(AND(I$27=20,$E$24>1),$E$11*(1+Supuestos!$B$5)^MAX($E$12-1,0)*MAX(0,1-(20-$E$12)/$E$24),0) | J33: =IF(AND(J$27=20,$E$24>1),$E$11*(1+Supuestos!$B$5)^MAX($E$12-1,0)*MAX(0,1-(20-$E$12)/$E$24),0) | ... W33: =IF(AND(W$27=20,$E$24>1),$E$11*(1+Supuestos!$B$5)^MAX($E$12-1,0)*MAX(0,1-(20-$E$12)/$E$24),0)
A34: Inversión | C34: =C28 | D34: =D28 | E34: =E28 | F34: =F28 | G34: =G28 | H34: =H28 | I34: =I28 | J34: =J28 | ... W34: =W28
A35: Ingresos cobrados | C35: =C29 | D35: =D29 | E35: =E29 | F35: =F29 | G35: =G29 | H35: =H29 | I35: =I29 | J35: =J29 | ... W35: =W29
A36: Gastos | C36: =C30 | D36: =D30 | E36: =E30 | F36: =F30 | G36: =G30 | H36: =H30 | I36: =I30 | J36: =J30 | ... W36: =W30
A37: Impuestos | C37: =C31 | D37: =D31 | E37: =E31 | F37: =F31 | G37: =G31 | H37: =H31 | I37: =I31 | J37: =J31 | ... W37: =W31
A38: Reposiciones | C38: =C32 | D38: =D32 | E38: =E32 | F38: =F32 | G38: =G32 | H38: =H32 | I38: =I32 | J38: =J32 | ... W38: =W32
A39: Valor residual (año 20) | C39: =C33 | D39: =D33 | E39: =E33 | F39: =F33 | G39: =G33 | H39: =H33 | I39: =I33 | J39: =J33 | ... W39: =W33
A40: FLUJO NETO | C40: =C34+C35+C36+C37+C38+C39 | D40: =D34+D35+D36+D37+D38+D39 | E40: =E34+E35+E36+E37+E38+E39 | F40: =F34+F35+F36+F37+F38+F39 | G40: =G34+G35+G36+G37+G38+G39 | H40: =H34+H35+H36+H37+H38+H39 | I40: =I34+I35+I36+I37+I38+I39 | J40: =J34+J35+J36+J37+J38+J39 | ... W40: =W34+W35+W36+W37+W38+W39
A41: Caja acumulada (sin valor residual) | C41: =C40-C39 | D41: =C41+D40-D39 | E41: =D41+E40-E39 | F41: =E41+F40-F39 | G41: =F41+G40-G39 | H41: =G41+H40-H39 | I41: =H41+I40-I39 | J41: =I41+J40-J39 | K41: =J41+K40-K39 | ... W41: =V41+W40-W39
A42: Flujo del propietario contando el terreno (lo aporta hoy y lo recupera valorizado) | C42: =C40-Supuestos!$B$21 | D42: =D40 | E42: =E40 | F42: =F40 | G42: =G40 | H42: =H40 | I42: =I40 | J42: =J40 | K42: =K40 | ... V42: =V40 | W42: =W40+Supuestos!$B$21*(1+Supuestos!$B$23)^20
...

Sheet C Locales + cochera
A1: C. Locales en la esquina y el jirón + cochera de abonados
A2: Franja comercial de 8 m de fondo sobre el jirón y la esquina (ancla de 100 m² + 3 locales de 39-48 m²), estructura para 2 pisos más y 12 plazas de abonados atrás (las otras 6 quedan para los locales), con ingreso y salida por la calle lateral.
A4: Fase 1: Local de esquina (100 m²)
A5: Partida | B5: Und. | C5: Cantidad | D5: P. unitario | E5: Parcial
A6: Local de esquina de 100 m² en pórticos de C.A. diseñados para 3 pisos, puertas enrollables y SS.HH. | B6: m² | C6: 100 | D6: 1500 | E6: =C6*D6
A7: Estudio de suelos, proyecto y licencia | B7: glb | C7: 1 | D7: 20000 | E7: =C7*D7
D8: Inversión (con imprevistos y factor de escenario) | E8: =SUM(E6:E7)*(1+Supuestos!$B$6)*Supuestos!$B$22
D9: Año de inversión (opera desde el año siguiente) | E9: 0
D10: Ingreso bruto potencial S/ por mes - pesimista | E10: 1000
D11: Ingreso bruto potencial S/ por mes - base | E11: 1300
D12: Ingreso bruto potencial S/ por mes - optimista | E12: 2000
D13: Ocupación cobrada - pesimista | E13: 0.7
D14: Ocupación cobrada - base | E14: 0.8
D15: Ocupación cobrada - optimista | E15: 0.9
D16: Gastos fijos S/ por año (personal, energía, mantenimiento, seguro, predial) | E16: 2500
D17: Gastos variables (% del ingreso cobrado) | E17: 0
D18: Impuestos (% del ingreso cobrado) | E18: 0.05
D19: Ingreso relativo 1.er año de operación | E19: 0.5
D20: Ingreso relativo 2.º año de operación | E20: 0.8
D21: Vida útil para valor residual (años) | E21: 50
A23: Fase 2: 3 locales al jirón + núcleo de escalera
A24: Partida | B24: Und. | C24: Cantidad | D24: P. unitario | E24: Parcial
A25: 3 locales de 39-48 m² (134.7 m²) y núcleo de escalera, SS.HH. y depósito de 26 m² junto a B, en pórticos de C.A. diseñados para 3 pisos | B25: m² | C25: 160.6 | D25: 1500 | E25: =C25*D25
A26: Ampliación del proyecto y licencia | B26: glb | C26: 1 | D26: 12000 | E26: =C26*D26
D27: Inversión (con imprevistos y factor de escenario) | E27: =SUM(E25:E26)*(1+Supuestos!$B$6)*Supuestos!$B$22
D28: Año de inversión (opera desde el año siguiente) | E28: 0
D29: Ingreso bruto potencial S/ por mes - pesimista | E29: 1616.4
D30: Ingreso bruto potencial S/ por mes - base | E30: 2020.5
D31: Ingreso bruto potencial S/ por mes - optimista | E31: 2424.6
D32: Ocupación cobrada - pesimista | E32: 0.7
D33: Ocupación cobrada - base | E33: 0.8
D34: Ocupación cobrada - optimista | E34: 0.9
D35: Gastos fijos S/ por año (personal, energía, mantenimiento, seguro, predial) | E35: 3600
D36: Gastos variables (% del ingreso cobrado) | E36: 0
D37: Impuestos (% del ingreso cobrado) | E37: 0.05
D38: Ingreso relativo 1.er año de operación | E38: 0.5
D39: Ingreso relativo 2.º año de operación | E39: 0.8
D40: Vida útil para valor residual (años) | E40: 50
A42: Fase 3: Cochera de abonados (fondo, descubierta)
A43: Partida | B43: Und. | C43: Cantidad | D43: P. unitario | E43: Parcial
...

Sheet A Estac. techado
A1: A. Estacionamiento techado (anteproyecto actual)
A2: 28 plazas techadas con estructura metálica, 5 motos y 2 mototaxis; guardián contratado.
A4: Fase 1: Estacionamiento techado
D5: Inversión (calculada en su propio modelo, por factor de escenario) | E5: =308524.26*Supuestos!$B$22
D6: Año de inversión (opera desde el año siguiente) | E6: 0
D7: Ingreso bruto potencial S/ por mes - pesimista | E7: 1890
D8: Ingreso bruto potencial S/ por mes - base | E8: 2855
D9: Ingreso bruto potencial S/ por mes - optimista | E9: 4330
D10: Ocupación cobrada - pesimista | E10: 1
D11: Ocupación cobrada - base | E11: 1
D12: Ocupación cobrada - optimista | E12: 1
D13: Gastos fijos S/ por año (personal, energía, mantenimiento, seguro, predial) | E13: 27005.81
D14: Gastos variables (% del ingreso cobrado) | E14: 0
D15: Impuestos (% del ingreso cobrado) | E15: 0
D16: Ingreso relativo 1.er año de operación | E16: 0.6
D17: Ingreso relativo 2.º año de operación | E17: 0.85
... D20: Reposición 1: monto a precios de hoy | E20: 18511.456
A22: FLUJO DE CAJA (S/ nominales)
A23: Concepto / año | C23: 0 | D23: 1 | E23: 2 | F23: 3 | G23: 4 | H23: 5 | I23: 6 | J23: 7 | K23: 8 | L23: 9 | M23: 10 | N23: 11 | O23: 12 | P23: 13 | Q23: 14 | R23: 15 | S23: 16 | T23: 17 | U23: 18 | V23: 19 | W23: 20
A24: Inversión - fase 1 | C24: =IF(C$23=$E$6,-$E$5*(1+Supuestos!$B$5)^MAX($E$6-1,0),0) | D24: =IF(D$23=$E$6,-$E$5*(1+Supuestos!$B$5)^MAX($E$6-1,0),0) | E24: =IF(E$23=$E$6,-$E$5*(1+Supuestos!$B$5)^MAX($E$6-1,0),0) | F24: =IF(F$23=$E$6,-$E$5*(1+Supuestos!$B$5)^MAX($E$6-1,0),0) | G24: =IF(G$23=$E$6,-$E$5*(1+Supuestos!$B$5)^MAX($E$6-1,0),0) | H24: =IF(H$23=$E$6,-$E$5*(1+Supuestos!$B$5)^MAX($E$6-1,0),0) | I24: =IF(I$23=$E$6,-$E$5*(1+Supuestos!$B$5)^MAX($E$6-1,0),0) | J24: =IF(J$23=$E$6,-$E$5*(1+Supuestos!$B$5)^MAX($E$6-1,0),0) | ... W24: =IF(W$23=$E$6,-$E$5*(1+Supuestos!$B$5)^MAX($E$6-1,0),0)
A25: Ingresos cobrados - fase 1 | C25: =IF((C$23-$E$6)>=1,CHOOSE(Supuestos!$B$3,$E$7,$E$8,$E$9)*12*CHOOSE(Supuestos!$B$3,$E$10,$E$11,$E$12)*IF((C$23-$E$6)=1,$E$16,IF((C$23-$E$6)=2,$E$17,1))*(1+Supuestos!$B$5)^MAX(C$23-1,0),0) | D25: =IF((D$23-$E$6)>=1,CHOOSE(Supuestos!$B$3,$E$7,$E$8,$E$9)*12*CHOOSE(Supuestos!$B$3,$E$10,$E$11,$E$12)*IF((D$23-$E$6)=1,$E$16,IF((D$23-$E$6)=2,$E$17,1))*(1+Supuestos!$B$5)^MAX(D$23-1,0),0) | E25: =IF((E$23-$E$6)>=1,CHOOSE(Supuestos!$B$3,$E$7,$E$8,$E$9)*12*CHOOSE(Supuestos!$B$3,$E$10,$E$11,$E$12)*IF((E$23-$E$6)=1,$E$16,IF((E$23-$E$6)=2,$E$17,1))*(1+Supuestos!$B$5)^MAX(E$23-1,0),0) | F25: =IF((F$23-$E$6)>=1,CHOOSE(Supuestos!$B$3,$E$7,$E$8,$E$9)*12*CHOOSE(Supuestos!$B$3,$E$10,$E$11,$E$12)*IF((F$23-$E$6)=1,$E$16,IF((F$23-$E$6)=2,$E$17,1))*(1+Supuestos!$B$5)^MAX(F$23-1,0),0) | G25: =IF((G$23-$E$6)>=1,CHOOSE(Supuestos!$B$3,$E$7,$E$8,$E$9)*12*CHOOSE(Supuestos!$B$3,$E$10,$E$11,$E$12)*IF((G$23-$E$6)=1,$E$16,IF((G$23-$E$6)=2,$E$17,1))*(1+Supuestos!$B$5)^MAX(G$23-1,0),0) | H25: =IF((H$23-$E$6)>=1,CHOOSE(Supuestos!$B$3,$E$7,$E$8,$E$9)*12*CHOOSE(Supuestos!$B$3,$E$10,$E$11,$E$12)*IF((H$23-$E$6)=1,$E$16,IF((H$23-$E$6)=2,$E$17,1))*(1+Supuestos!$B$5)^MAX(H$23-1,0),0) | I25: =IF((I$23-$E$6)>=1,CHOOSE(Supuestos!$B$3,$E$7,$E$8,$E$9)*12*CHOOSE(Supuestos!$B$3,$E$10,$E$11,$E$12)*IF((I$23-$E$6)=1,$E$16,IF((I$23-$E$6)=2,$E$17,1))*(1+Supuestos!$B$5)^MAX(I$23-1,0),0) | J25: =IF((J$23-$E$6)>=1,CHOOSE(Supuestos!$B$3,$E$7,$E$8,$E$9)*12*CHOOSE(Supuestos!$B$3,$E$10,$E$11,$E$12)*IF((J$23-$E$6)=1,$E$16,IF((J$23-$E$6)=2,$E$17,1))*(1+Supuestos!$B$5)^MAX(J$23-1,0),0) | ... W25: =IF((W$23-$E$6)>=1,CHOOSE(Supuestos!$B$3,$E$7,$E$8,$E$9)*12*CHOOSE(Supuestos!$B$3,$E$10,$E$11,$E$12)*IF((W$23-$E$6)=1,$E$16,IF((W$23-$E$6)=2,$E$17,1))*(1+Supuestos!$B$5)^MAX(W$23-1,0),0)
A26: Gastos - fase 1 | C26: =IF((C$23-$E$6)>=1,-$E$13*(1+Supuestos!$B$5)^MAX(C$23-1,0)-$E$14*C25,0) | D26: =IF((D$23-$E$6)>=1,-$E$13*(1+Supuestos!$B$5)^MAX(D$23-1,0)-$E$14*D25,0) | E26: =IF((E$23-$E$6)>=1,-$E$13*(1+Supuestos!$B$5)^MAX(E$23-1,0)-$E$14*E25,0) | F26: =IF((F$23-$E$6)>=1,-$E$13*(1+Supuestos!$B$5)^MAX(F$23-1,0)-$E$14*F25,0) | G26: =IF((G$23-$E$6)>=1,-$E$13*(1+Supuestos!$B$5)^MAX(G$23-1,0)-$E$14*G25,0) | H26: =IF((H$23-$E$6)>=1,-$E$13*(1+Supuestos!$B$5)^MAX(H$23-1,0)-$E$14*H25,0) | I26: =IF((I$23-$E$6)>=1,-$E$13*(1+Supuestos!$B$5)^MAX(I$23-1,0)-$E$14*I25,0) | J26: =IF((J$23-$E$6)>=1,-$E$13*(1+Supuestos!$B$5)^MAX(J$23-1,0)-$E$14*J25,0) | ... W26: =IF((W$23-$E$6)>=1,-$E$13*(1+Supuestos!$B$5)^MAX(W$23-1,0)-$E$14*W25,0)
A27: Impuestos - fase 1 | C27: =-$E$15*C25 | D27: =-$E$15*D25 | E27: =-$E$15*E25 | F27: =-$E$15*F25 | G27: =-$E$15*G25 | H27: =-$E$15*H25 | I27: =-$E$15*I25 | J27: =-$E$15*J25 | ... W27: =-$E$15*W25
A28: Reposiciones - fase 1 | C28: =IF((C$23-$E$6)=$E$19,-$E$20*(1+Supuestos!$B$5)^MAX(C$23-1,0)*Supuestos!$B$22,0) | D28: =IF((D$23-$E$6)=$E$19,-$E$20*(1+Supuestos!$B$5)^MAX(D$23-1,0)*Supuestos!$B$22,0) | E28: =IF((E$23-$E$6)=$E$19,-$E$20*(1+Supuestos!$B$5)^MAX(E$23-1,0)*Supuestos!$B$22,0) | F28: =IF((F$23-$E$6)=$E$19,-$E$20*(1+Supuestos!$B$5)^MAX(F$23-1,0)*Supuestos!$B$22,0) | G28: =IF((G$23-$E$6)=$E$19,-$E$20*(1+Supuestos!$B$5)^MAX(G$23-1,0)*Supuestos!$B$22,0) | H28: =IF((H$23-$E$6)=$E$19,-$E$20*(1+Supuestos!$B$5)^MAX(H$23-1,0)*Supuestos!$B$22,0) | I28: =IF((I$23-$E$6)=$E$19,-$E$20*(1+Supuestos!$B$5)^MAX(I$23-1,0)*Supuestos!$B$22,0) | J28: =IF((J$23-$E$6)=$E$19,-$E$20*(1+Supuestos!$B$5)^MAX(J$23-1,0)*Supuestos!$B$22,0) | ... W28: =IF((W$23-$E$6)=$E$19,-$E$20*(1+Supuestos!$B$5)^MAX(W$23-1,0)*Supuestos!$B$22,0)
A29: Valor residual (año 20) - fase 1 | C29: =IF(AND(C$23=20,$E$18>1),$E$5*(1+Supuestos!$B$5)^MAX($E$6-1,0)*MAX(0,1-(20-$E$6)/$E$18),0) | D29: =IF(AND(D$23=20,$E$18>1),$E$5*(1+Supuestos!$B$5)^MAX($E$6-1,0)*MAX(0,1-(20-$E$6)/$E$18),0) | E29: =IF(AND(E$23=20,$E$18>1),$E$5*(1+Supuestos!$B$5)^MAX($E$6-1,0)*MAX(0,1-(20-$E$6)/$E$18),0) | F29: =IF(AND(F$23=20,$E$18>1),$E$5*(1+Supuestos!$B$5)^MAX($E$6-1,0)*MAX(0,1-(20-$E$6)/$E$18),0) | G29: =IF(AND(G$23=20,$E$18>1),$E$5*(1+Supuestos!$B$5)^MAX($E$6-1,0)*MAX(0,1-(20-$E$6)/$E$18),0) | H29: =IF(AND(H$23=20,$E$18>1),$E$5*(1+Supuestos!$B$5)^MAX($E$6-1,0)*MAX(0,1-(20-$E$6)/$E$18),0) | I29: =IF(AND(I$23=20,$E$18>1),$E$5*(1+Supuestos!$B$5)^MAX($E$6-1,0)*MAX(0,1-(20-$E$6)/$E$18),0) | J29: =IF(AND(J$23=20,$E$18>1),$E$5*(1+Supuestos!$B$5)^MAX($E$6-1,0)*MAX(0,1-(20-$E$6)/$E$18),0) | ... W29: =IF(AND(W$23=20,$E$18>1),$E$5*(1+Supuestos!$B$5)^MAX($E$6-1,0)*MAX(0,1-(20-$E$6)/$E$18),0)
A30: Inversión | C30: =C24 | D30: =D24 | E30: =E24 | F30: =F24 | G30: =G24 | H30: =H24 | I30: =I24 | J30: =J24 | ... W30: =W24
A31: Ingresos cobrados | C31: =C25 | D31: =D25 | E31: =E25 | F31: =F25 | G31: =G25 | H31: =H25 | I31: =I25 | J31: =J25 | ... W31: =W25
A32: Gastos | C32: =C26 | D32: =D26 | E32: =E26 | F32: =F26 | G32: =G26 | H32: =H26 | I32: =I26 | J32: =J26 | ... W32: =W26
A33: Impuestos | C33: =C27 | D33: =D27 | E33: =E27 | F33: =F27 | G33: =G27 | H33: =H27 | I33: =I27 | J33: =J27 | ... W33: =W27
A34: Reposiciones | C34: =C28 | D34: =D28 | E34: =E28 | F34: =F28 | G34: =G28 | H34: =H28 | I34: =I28 | J34: =J28 | ... W34: =W28
A35: Valor residual (año 20) | C35: =C29 | D35: =D29 | E35: =E29 | F35: =F29 | G35: =G29 | H35: =H29 | I35: =I29 | J35: =J29 | ... W35: =W29
A36: FLUJO NETO | C36: =C30+C31+C32+C33+C34+C35 | D36: =D30+D31+D32+D33+D34+D35 | E36: =E30+E31+E32+E33+E34+E35 | F36: =F30+F31+F32+F33+F34+F35 | G36: =G30+G31+G32+G33+G34+G35 | H36: =H30+H31+H32+H33+H34+H35 | I36: =I30+I31+I32+I33+I34+I35 | J36: =J30+J31+J32+J33+J34+J35 | ... W36: =W30+W31+W32+W33+W34+W35
A37: Caja acumulada (sin valor residual) | C37: =C36-C35 | D37: =C37+D36-D35 | E37: =D37+E36-E35 | F37: =E37+F36-F35 | G37: =F37+G36-G35 | H37: =G37+H36-H35 | I37: =H37+I36-I35 | J37: =I37+J36-J35 | K37: =J37+K36-K35 | ... W37: =V37+W36-W35
A38: Flujo del propietario contando el terreno (lo aporta hoy y lo recupera valorizado) | C38: =C36-Supuestos!$B$21 | D38: =D36 | E38: =E36 | F38: =F36 | G38: =G36 | H38: =H36 | I38: =I36 | J38: =J36 | K38: =K36 | ... V38: =V36 | W38: =W36+Supuestos!$B$21*(1+Supuestos!$B$23)^20
A40: Inversión total | C40: =-SUM(C30:W30)
A41: VAN al 10% | C41: =C36+NPV(Supuestos!$B$4,D36:W36)
A42: TIR | C42: =IFERROR(IRR(C36:W36),IFERROR(IRR(C36:W36,-0.05),"no aplica"))
A43: Año en que se recupera la inversión (acumulado ≥ 0) | C43: =IF(-SUM(C30:W30)=0,"sin inversión",IFERROR(INDEX(C23:W23,MATCH(TRUE,INDEX(C37:W37>=0,0),0)),"no en 20 años"))
A44: Caja neta del año 5 sin inversiones (S/ nominales) | C44: =H36-H30
A45: TIR contando el terreno | C45: =IFERROR(IRR(C38:W38),"no aplica")

Sheet F Cancha techada
A1: F. Cancha sintética techada (fulbito)
A2: Cancha recreativa de 25 × 15 m (sin franja de seguridad; con franja de 1 m ≈ 25 × 14), techada por la lluvia, con vestuarios y caseta.
A4: Fase 1: Cancha sintética techada
A5: Partida | B5: Und. | C5: Cantidad | D5: P. unitario | E5: Parcial
A6: Base granular, losa de nivelación y drenaje | B6: m² | C6: 450 | D6: 70 | E6: =C6*D6
A7: Grass sintético instalado (25 × 15 m + bandas) | B7: m² | C7: 400 | D7: 115 | E7: =C7*D7
A8: Estructura metálica y cobertura TR-4 sobre la cancha | B8: m² | C8: 570 | D8: 330 | E8: =C8*D8
A9: Mallas perimetrales, arcos y redes | B9: glb | C9: 1 | D9: 9000 | E9: =C9*D9
A10: Iluminación LED (8 kW) | B10: glb | C10: 1 | D10: 14000 | E10: =C10*D10
A11: Vestuarios, SS.HH. y caseta (albañilería) | B11: m² | C11: 40 | D11: 1300 | E11: =C11*D11
A12: Cerco de albañilería en frentes y portones | B12: ml | C12: 50 | D12: 330 | E12: =C12*D12
A13: Expediente y licencias | B13: glb | C13: 1 | D13: 15000 | E13: =C13*D13
D14: Inversión (con imprevistos y factor de escenario) | E14: =SUM(E6:E13)*(1+Supuestos!$B$6)*Supuestos!$B$22
D15: Año de inversión (opera desde el año siguiente) | E15: 0
D16: Ingreso bruto potencial S/ por mes - pesimista | E16: 2700
D17: Ingreso bruto potencial S/ por mes - base | E17: 3750
D18: Ingreso bruto potencial S/ por mes - optimista | E18: 5775
D19: Ocupación cobrada - pesimista | E19: 1
D20: Ocupación cobrada - base | E20: 1
D21: Ocupación cobrada - optimista | E21: 1
D22: Gastos fijos S/ por año (personal, energía, mantenimiento, seguro, predial) | E22: 30645.4
D23: Gastos variables (% del ingreso cobrado) | E23: 0
D24: Impuestos (% del ingreso cobrado) | E24: 0
D25: Ingreso relativo 1.er año de operación | E25: 0.7
D26: Ingreso relativo 2.º año de operación | E26: 0.9
... D31: Reposición 2: monto a precios de hoy | E31: 50600
A33: FLUJO DE CAJA (S/ nominales)
A34: Concepto / año | C34: 0 | D34: 1 | E34: 2 | F34: 3 | G34: 4 | H34: 5 | I34: 6 | J34: 7 | K34: 8 | L34: 9 | M34: 10 | N34: 11 | O34: 12 | P34: 13 | Q34: 14 | R34: 15 | S34: 16 | T34: 17 | U34: 18 | V34: 19 | W34: 20
A35: Inversión - fase 1 | C35: =IF(C$34=$E$15,-$E$14*(1+Supuestos!$B$5)^MAX($E$15-1,0),0) | D35: =IF(D$34=$E$15,-$E$14*(1+Supuestos!$B$5)^MAX($E$15-1,0),0) | E35: =IF(E$34=$E$15,-$E$14*(1+Supuestos!$B$5)^MAX($E$15-1,0),0) | F35: =IF(F$34=$E$15,-$E$14*(1+Supuestos!$B$5)^MAX($E$15-1,0),0) | G35: =IF(G$34=$E$15,-$E$14*(1+Supuestos!$B$5)^MAX($E$15-1,0),0) | H35: =IF(H$34=$E$15,-$E$14*(1+Supuestos!$B$5)^MAX($E$15-1,0),0) | I35: =IF(I$34=$E$15,-$E$14*(1+Supuestos!$B$5)^MAX($E$15-1,0),0) | J35: =IF(J$34=$E$15,-$E$14*(1+Supuestos!$B$5)^MAX($E$15-1,0),0) | ... W35: =IF(W$34=$E$15,-$E$14*(1+Supuestos!$B$5)^MAX($E$15-1,0),0)
A36: Ingresos cobrados - fase 1 | C36: =IF((C$34-$E$15)>=1,CHOOSE(Supuestos!$B$3,$E$16,$E$17,$E$18)*12*CHOOSE(Supuestos!$B$3,$E$19,$E$20,$E$21)*IF((C$34-$E$15)=1,$E$25,IF((C$34-$E$15)=2,$E$26,1))*(1+Supuestos!$B$5)^MAX(C$34-1,0),0) | D36: =IF((D$34-$E$15)>=1,CHOOSE(Supuestos!$B$3,$E$16,$E$17,$E$18)*12*CHOOSE(Supuestos!$B$3,$E$19,$E$20,$E$21)*IF((D$34-$E$15)=1,$E$25,IF((D$34-$E$15)=2,$E$26,1))*(1+Supuestos!$B$5)^MAX(D$34-1,0),0) | E36: =IF((E$34-$E$15)>=1,CHOOSE(Supuestos!$B$3,$E$16,$E$17,$E$18)*12*CHOOSE(Supuestos!$B$3,$E$19,$E$20,$E$21)*IF((E$34-$E$15)=1,$E$25,IF((E$34-$E$15)=2,$E$26,1))*(1+Supuestos!$B$5)^MAX(E$34-1,0),0) | F36: =IF((F$34-$E$15)>=1,CHOOSE(Supuestos!$B$3,$E$16,$E$17,$E$18)*12*CHOOSE(Supuestos!$B$3,$E$19,$E$20,$E$21)*IF((F$34-$E$15)=1,$E$25,IF((F$34-$E$15)=2,$E$26,1))*(1+Supuestos!$B$5)^MAX(F$34-1,0),0) | G36: =IF((G$34-$E$15)>=1,CHOOSE(Supuestos!$B$3,$E$16,$E$17,$E$18)*12*CHOOSE(Supuestos!$B$3,$E$19,$E$20,$E$21)*IF((G$34-$E$15)=1,$E$25,IF((G$34-$E$15)=2,$E$26,1))*(1+Supuestos!$B$5)^MAX(G$34-1,0),0) | H36: =IF((H$34-$E$15)>=1,CHOOSE(Supuestos!$B$3,$E$16,$E$17,$E$18)*12*CHOOSE(Supuestos!$B$3,$E$19,$E$20,$E$21)*IF((H$34-$E$15)=1,$E$25,IF((H$34-$E$15)=2,$E$26,1))*(1+Supuestos!$B$5)^MAX(H$34-1,0),0) | I36: =IF((I$34-$E$15)>=1,CHOOSE(Supuestos!$B$3,$E$16,$E$17,$E$18)*12*CHOOSE(Supuestos!$B$3,$E$19,$E$20,$E$21)*IF((I$34-$E$15)=1,$E$25,IF((I$34-$E$15)=2,$E$26,1))*(1+Supuestos!$B$5)^MAX(I$34-1,0),0) | J36: =IF((J$34-$E$15)>=1,CHOOSE(Supuestos!$B$3,$E$16,$E$17,$E$18)*12*CHOOSE(Supuestos!$B$3,$E$19,$E$20,$E$21)*IF((J$34-$E$15)=1,$E$25,IF((J$34-$E$15)=2,$E$26,1))*(1+Supuestos!$B$5)^MAX(J$34-1,0),0) | ... W36: =IF((W$34-$E$15)>=1,CHOOSE(Supuestos!$B$3,$E$16,$E$17,$E$18)*12*CHOOSE(Supuestos!$B$3,$E$19,$E$20,$E$21)*IF((W$34-$E$15)=1,$E$25,IF((W$34-$E$15)=2,$E$26,1))*(1+Supuestos!$B$5)^MAX(W$34-1,0),0)
A37: Gastos - fase 1 | C37: =IF((C$34-$E$15)>=1,-$E$22*(1+Supuestos!$B$5)^MAX(C$34-1,0)-$E$23*C36,0) | D37: =IF((D$34-$E$15)>=1,-$E$22*(1+Supuestos!$B$5)^MAX(D$34-1,0)-$E$23*D36,0) | E37: =IF((E$34-$E$15)>=1,-$E$22*(1+Supuestos!$B$5)^MAX(E$34-1,0)-$E$23*E36,0) | F37: =IF((F$34-$E$15)>=1,-$E$22*(1+Supuestos!$B$5)^MAX(F$34-1,0)-$E$23*F36,0) | G37: =IF((G$34-$E$15)>=1,-$E$22*(1+Supuestos!$B$5)^MAX(G$34-1,0)-$E$23*G36,0) | H37: =IF((H$34-$E$15)>=1,-$E$22*(1+Supuestos!$B$5)^MAX(H$34-1,0)-$E$23*H36,0) | I37: =IF((I$34-$E$15)>=1,-$E$22*(1+Supuestos!$B$5)^MAX(I$34-1,0)-$E$23*I36,0) | J37: =IF((J$34-$E$15)>=1,-$E$22*(1+Supuestos!$B$5)^MAX(J$34-1,0)-$E$23*J36,0) | ... W37: =IF((W$34-$E$15)>=1,-$E$22*(1+Supuestos!$B$5)^MAX(W$34-1,0)-$E$23*W36,0)
A38: Impuestos - fase 1 | C38: =-$E$24*C36 | D38: =-$E$24*D36 | E38: =-$E$24*E36 | F38: =-$E$24*F36 | G38: =-$E$24*G36 | H38: =-$E$24*H36 | I38: =-$E$24*I36 | J38: =-$E$24*J36 | ... W38: =-$E$24*W36
